Workbook

Sheet README
A1: SETTLEMENTS — CATALOGUE WORKBOOK
A2: Empty tables for every catalogue in the system. Fill them in; nothing here is generated from the current rules.
A4: How to use this workbook
A6: One sheet per catalogue. | B6: Type your entries under the header row.
A7: Row 2 is a GREY EXAMPLE. | B7: It shows the expected format. Delete it when you start — it is ignored on import, and the Progress count below includes it until you do.
A8: Do not rename sheets or headers. | B8: The importer matches on both. Adding a column at the right-hand end is safe.
A9: Leave a cell blank if unknown. | B9: Blank is honest. A guessed number is the defect this rebuild exists to remove.
A11: The Conf column
A12: A | B12: Measured, current, statistically significant — trust it for play.
A13: B | B13: Measured, but wide CI or single-scenario coverage only — usable, expect movement.
A14: C | B14: Derived by rule from an A/B atom, never measured directly — placeholder.
A15: (blank) | B15: Not costed yet. This is the one the old catalogues kept hiding.
A17: The Ruled column
A18: (blank) or Ross | B18: You decided it. This is the default — leave it blank and it means yours.
A19: derived | B19: Worked out from another rule rather than decided. Fine to keep, but it is an inference, not a ruling.
A20: carried-over | B20: Brought in from the old system without being re-checked.
A21: unruled | B21: Placeholder. Nobody has actually decided this yet.
A22: Why it exists | B22: "Only a Leader ever reaches T3" was a derived gloss that entered with the master doc on 2026-08-05, restating a July cap table — then got quoted back at you as a design constraint you never set. This column makes that impossible to repeat.
A24: Sheets that are new
A25: Chems, Drones | B25: No catalogue exists in the rules today. Both are named in the setting and referenced by built structures.
A26: Weapon Drawbacks | B26: Split out from Characteristics — a refund is a price, and they were never tiered.
A27: Scenario Twists, Glorious Deeds, | B27: Existed in the rules but never as their own catalogue.
A28: Fate Table, Injuries & Scars
A30: Progress
A31: Catalogue | B31: Rows
A32: Ranks | B32: =COUNTA('Ranks'!A2:A400)
A33: Skills | B33: =COUNTA('Skills'!A2:A400)
A34: Progression | B34: =COUNTA('Progression'!A2:A400)
A35: Weapon Classes | B35: =COUNTA('Weapon Classes'!A2:A400)
A36: Weapon Characteristics | B36: =COUNTA('Weapon Characteristics'!A2:A400)
A37: Weapon Drawbacks | B37: =COUNTA('Weapon Drawbacks'!A2:A400)
A38: Armour | B38: =COUNTA('Armour'!A2:A400)
A39: Equipment | B39: =COUNTA('Equipment'!A2:A400)
A40: Chems | B40: =COUNTA('Chems'!A2:A400)
A41: Drones | B41: =COUNTA('Drones'!A2:A400)
A42: Turrets | B42: =COUNTA('Turrets'!A2:A400)
A43: Mine Chassis | B43: =COUNTA('Mine Chassis'!A2:A400)
A44: Mine Payloads | B44: =COUNTA('Mine Payloads'!A2:A400)
A45: Traps | B45: =COUNTA('Traps'!A2:A400)
A46: Beacons | B46: =COUNTA('Beacons'!A2:A400)
...

Sheet Ranks
A1: Rank | B1: Stat Points | C1: Orders | D1: Credits | E1: Conf | F1: Tier Caps at Creation | G1: Notes | H1: Ruled
A2: Fighter | B2: 5 | C2: 0 | D2: 100 | E2: A | F2: 2 x T1 | G2: The workhorse; first rank that may carry Standard Ranged | H2: Ross

Sheet Skills
A1: Skill | B1: Stat | C1: Tier | D1: Effect | E1: Role | F1: Notes | G1: Ruled
A2: Bank Shot | B2: DEX | C2: T1 | D2: When Heavy Cover causes your ranged attack to miss by exactly 1, a target touching that cover becomes Pinned; make no Injury roll. | E2: Suppressor | G2: Ross

Sheet Progression
A1: Level | B1: Grants | C1: Notes | D1: Ruled
A2: 3 | B2: Skill slot — any path that stat has unlocked | C2: First skill slot of the track | D2: Ross

Sheet Weapon Classes
A1: Class | B1: Dmg Min | C1: Dmg Max | D1: Range Min | E1: Range Max | F1: Hands | G1: Min Rank | H1: Slots | I1: Base Cr | J1: Conf | K1: Always Has | L1: Ruled
A2: Standard Ranged | B2: 2 | C2: 4 | D2: 12 | E2: 36 | F2: 2 | G2: Fighter | H2: 3 | I2: 15 | J2: A | K2: Two-Handed, Loud | L2: Ross

Sheet Weapon Characteristics
A1: Characteristic | B1: Category | C1: Cr | D1: Conf | E1: Restriction | F1: Effect | G1: Ruled
A2: Brutal | B2: Damage & armour | C2: 10 | D2: A | E2: Melee, or ranged with Short Range | F2: +1 Damage, to the class band's ceiling (max +5). | G2: Ross

Sheet Weapon Drawbacks
A1: Drawback | B1: Refund | C1: Conf | D1: Restriction | E1: Effect | F1: Ruled
A2: Slow | B2: -5 | C2: C | D2: Melee only | E2: You may not Charge with this weapon. | F2: Ross

Sheet Armour
A1: Armour | B1: Injury Mod | C1: Cr | D1: Conf | E1: Drawback | F1: Notes | G1: Ruled
A2: Light | B2: -1 | C2: 10 | D2: B | E2: None | F2: Measured directly with zero prior | G2: Ross

Sheet Equipment
A1: Equipment | B1: Slot | C1: Cr | D1: Conf | E1: When | F1: Effect | G1: Ruled
A2: Med-Kit | B2: 1 | C2: 20 | D2: C | E2: Combat | F2: Cancels the -2 on Stabilize and on treating Bleed & Poison. | G2: Ross

Sheet Chems
A1: Chem | B1: Cr | C1: Conf | D1: Duration | E1: Effect | F1: Dependence | G1: Ruled
A2: Combat Stim | B2: 15 | C2: C | D2: 1 activation | E2: +1 to melee and ranged attack rolls. | F2: NRV test or gain Dependence | G2: Ross

Sheet Drones
A1: Drone | B1: Category | C1: Cr | D1: Conf | E1: Bandwidth | F1: Profile | G1: Effect | H1: Ruled
A2: Recon Spotter | B2: Recon | C2: 25 | D2: C | E2: 1 | F2: MOV 10", WND 1 | G2: Spots for the crew within 12". | H2: Ross

Sheet Turrets
A1: Turret | B1: Build | C1: Cr | D1: Conf | E1: Range | F1: Profile | G1: Ruled
A2: Autoturret | B2: Complex -1 | C2: 10 | D2: B | E2: 18" | F2: One shot / round, Injury Damage +3. | G2: Ross

Sheet Mine Chassis
A1: Chassis | B1: Build | C1: Cr | D1: Conf | E1: Delivery | F1: Ruled
A2: Pressure | B2: Standard 0 | C2: 5 | D2: C | E2: Detonates when a model moves within 1". | F2: Ross

Sheet Mine Payloads
A1: Payload | B1: Cr | C1: Conf | D1: Effect | E1: Ruled
A2: Explosion | B2: 10 | C2: C | D2: Injury roll at Damage +3 against every model within 2". | E2: Ross

Sheet Traps
A1: Trap | B1: Build | C1: Cr | D1: Conf | E1: Trigger & Effect | F1: Ruled
A2: Trip Wire | B2: Standard 0 | C2: 5 | D2: C | E2: First model to cross is Pinned and stops. | F2: Ross

Sheet Beacons
A1: Beacon | B1: Build | C1: Cr | D1: Conf | E1: Aura (within 6") | F1: Ruled
A2: Munitions Beacon | B2: Complex -1 | C2: 5 | D2: C | E2: Allies: +1 to the Injury roll. | F2: Ross

Sheet Conditions
A1: Condition | B1: Group | C1: Clock | D1: Effect | E1: Cleared by | F1: Ruled
A2: Pinned | B2: Core combat | C2: Until cleared | D2: -1 to all rolls; clear with a Move. | E2: Moving, or a Rally | F2: Ross

Sheet Reactions
A1: Reaction | B1: Trigger | C1: Effect | D1: Cost | E1: Ruled
A2: Snap Shot | B2: Enemy ends a Move or Action in your forward LOS | C2: Make a normal ranged attack at the triggering enemy. | D2: Ready token | E2: Ross

Sheet Terrain Types
A1: Type | B1: Movement | C1: Cover | D1: Tags | E1: Notes | F1: Ruled
A2: Ruin | B2: Difficult | C2: Light | D2: Climbable, Searchable | E2: The default mid-board piece | F2: Ross

Sheet Terrain Hazards
A1: Hazard | B1: Trigger | C1: Effect | D1: Ruled
A2: Fire / burning ground | B2: Entering or starting in it | C2: Injury roll at Damage +2; gain Fire. | D2: Ross

Sheet Terrain Verbs
A1: Verb | B1: Tag | C1: Stat | D1: Resolution | E1: Notes | F1: Ruled
A2: Force door | B2: Breachable | C2: STR | D2: 7+ | E2: Attempt is Loud | F2: Ross

Sheet Infrastructure
A1: Feature | B1: Category | C1: Verbs | D1: Operate | E1: Effect | F1: Damage Keyword | G1: Ruled
A2: Cargo Crane | B2: Manipulation | C2: Shift Terrain / Displace | D2: INT hack or STR manual | E2: Move a Movable piece up to 4". | F2: CRUSH | G2: Ross

Sheet Structures
A1: Structure | B1: Category | C1: Class | D1: Size | E1: Power | F1: Materials | G1: Conf | H1: What it does | I1: Ruled
A2: Processor | B2: Convert | C2: Plant | D2: 3x5 | E2: -1 | F2: 45 | G2: C | H2: Materials gatherer — scrap to Materials | I2: Ross

Sheet Worker Benefits
A1: Structure | B1: Benefit | C1: Notes | D1: Ruled
A2: Processor | B2: +1 Materials per Settlement Phase | D2: Ross

Sheet Scenarios
A1: Scenario | B1: Shape | C1: Objective | D1: Scoring | E1: Notes | F1: Ruled
A2: Take a Hold | B2: Control | C2: Hold the central objective at the end of each round | D2: 1 VP per round held | E2: The most static of the five | F2: Ross

Sheet Scenario Twists
A1: d6 | B1: Twist | C1: Effect | D1: Ruled
A2: 1 | B2: Low light | C2: All ranged attacks beyond 12" are at -1. | D2: Ross

Sheet Factions
A1: Faction | B1: Battlefield Rule | C1: Settlement Affinity | D1: Notes | E1: Ruled
A2: Military | B2: Ready token survives a failed Reaction attempt | C2: +1 free Bunkhouse tier at founding | D2: Needs a number in the rule | E2: Ross

Sheet Loot Table
A1: d10 | B1: Result | C1: Ruled
A2: 2 | B2: +5 Credits | C2: Ross

Sheet Events
A1: Roll | B1: Event | C1: When | D1: Effect | E1: Ruled
A2: 3 | B2: Sudden downpour | C2: Battlefield | D2: Ranged attacks beyond 18" are at -1 for one round. | E2: Ross

Sheet Glorious Deeds
A1: Deed | B1: Trigger | C1: XP | D1: Notes | E1: Ruled
A2: Daredevil | B2: Leap a gap of 3" or more during an activation | C2: 1 | D2: Once per fighter per battle | E2: Ross

Sheet Fate Table
A1: Roll | B1: Result | C1: Effect | D1: Ruled
A2: 1 | B2: Dead | C2: The fighter is removed from the roster permanently. | D2: Ross

Sheet Injuries & Scars
A1: Roll | B1: Injury | C1: Effect | D1: Permanent | E1: Ruled
A2: 4 | B2: Broken arm | C2: -1 STR for the next battle | D2: No | E2: Ross
